Workbook

Sheet TITLE
A14: COLLEGE OF TECHNOLOGY AT FARMINGDALE
A15: SCHOOL OF APPLIED SOCIAL SCIENCES
A17: NET ZERO CARBON STUDY
A18: Farmingdale, New York
A20: SUCF Project #26325
A21: Concept Estimate
A24: 44263

Sheet BOE
B6: =TITLE!A14 -> COLLEGE OF TECHNOLOGY AT FARMINGDALE | I6: =TITLE!A24 -> 44263
B7: =TITLE!A17 -> NET ZERO CARBON STUDY
A9: BASIS OF ESTIMATE (B.O.E.)
A12: 1 | B12: SCC Concept Estimate is based on the following documents prepared by Urbahn Architects
B13: Net Zero Carbon Study- Draft Report dated 12/23/2020
A16: 2 | B16: Project Areas & Scope
A18: a. | B18: Option-1: Centralized Ground Source HVAC
A20: b. | B20: Option-2: Centralized Air Source HVAC
A22: c. | B22: Option-3: Distributed Heat Pump System
A24: 3 | B24: Estimate does excludes the following
A26: a. | B26: Design fee
A27: b. | B27: Overtime cost
A28: c. | B28: Environmental Abatements
A29: d. | B29: Artwork, Graphics, Banners and Flags
A30: e. | B30: Rock Excavation
A31: f. | B31: Dewatering
A32: g. | B32: Signage & Painting
A33: h. | B33: Construction contingency
A35: 4 | B35: Construction Schedule
B37: Construction State Date | F37: 44531
B38: Construction Mid Point Date | F38: 44986
B39: Construction End Date | F39: 45444
A41: 5 | B41: Markups
B43: The following Markups are included
B44: General Conditions | F44: 0.1
B45: General Contractor's Overhead & Profit | F45: 0.08
B46: Design Contingency | F46: 0.1
B47: Bid Contingency | F47: 0.05
B48: Escalation to the Midpoint | F48: 0.084375
B49: Escalation Rate 3.75% per year

Sheet SUM
B4: =TITLE!A14 -> COLLEGE OF TECHNOLOGY AT FARMINGDALE | I4: =TITLE!A24 -> 44263
B5: =TITLE!A17 -> NET ZERO CARBON STUDY
B6: =TITLE!A21 -> Concept Estimate
A8: SUMMARY OF TRADES
B10: Description | D10: =EST!E10 -> Option-1 | E10: =EST!G10 -> Option-2 | F10: =EST!I10 -> Option-3 | I10: Base Option
A12: =ROW()-11 -> 1 | B12: =EST!B13 -> 01-00-00 General Requirements | D12: =EST!F17 -> 2599528.9 | E12: =EST!H17 -> 2395183.6 | F12: =EST!J17 -> 2291411.6 | I12: 2573215.6 | N12: =D12-$I12 -> 26313.328 | O12: =E12-$I12 -> -178032.02 | P12: =F12-$I12 -> -281804.01
A13: =ROW()-11 -> 2 | B13: =EST!B19 -> 02-00-00 Existing Conditions | D13: =EST!F23 -> 0 | E13: =EST!H23 -> 0 | F13: =EST!J23 -> 0 | I13: 0 | N13: =D13-$I13 -> 0 | O13: =E13-$I13 -> 0 | P13: =F13-$I13 -> 0
A14: =ROW()-11 -> 3 | B14: =EST!B25 -> 03-00-00 Concrete | D14: =EST!F48 -> 2463438.7 | E14: =EST!H48 -> 2394333.1 | F14: =EST!J48 -> 2394333.1 | I14: 2463244.8 | N14: =D14-$I14 -> 193.9139 | O14: =E14-$I14 -> -68911.689 | P14: =F14-$I14 -> -68911.689
A15: =ROW()-11 -> 4 | B15: =EST!B50 -> 04-00-00 Masonry | D15: =EST!F54 -> 826463.26 | E15: =EST!H54 -> 805240.86 | F15: =EST!J54 -> 805240.86 | I15: 826644.94 | N15: =D15-$I15 -> -181.67956 | O15: =E15-$I15 -> -21404.08 | P15: =F15-$I15 -> -21404.08
A16: =ROW()-11 -> 5 | B16: =EST!B56 -> 05-00-00 Metals | D16: =EST!F91 -> 4147196 | E16: =EST!H91 -> 3988940 | F16: =EST!J91 -> 3957546.5 | I16: 4122195.6 | N16: =D16-$I16 -> 25000.415 | O16: =E16-$I16 -> -133255.62 | P16: =F16-$I16 -> -164649.06
A17: =ROW()-11 -> 6 | B17: =EST!B93 -> 06-00-00 Wood, Plastics, & Composites | D17: =EST!F100 -> 386314.25 | E17: =EST!H100 -> 376394.25 | F17: =EST!J100 -> 376394.25 | I17: 386209.57 | N17: =D17-$I17 -> 104.676 | O17: =E17-$I17 -> -9815.324 | P17: =F17-$I17 -> -9815.324
A18: =ROW()-11 -> 7 | B18: =EST!B102 -> 07-00-00 Thermal and Moisture Protection | D18: =EST!F117 -> 2013988 | E18: =EST!H117 -> 2007895.2 | F18: =EST!J117 -> 2007895.2 | I18: 2013988 | N18: =D18-$I18 -> -0.03945 | O18: =E18-$I18 -> -6092.8394 | P18: =F18-$I18 -> -6092.8394
A19: =ROW()-11 -> 8 | B19: =EST!B119 -> 08-00-00 Openings | D19: =EST!F139 -> 1787408 | E19: =EST!H139 -> 1783506.8 | F19: =EST!J139 -> 1759961.7 | I19: 1787407.8 | N19: =D19-$I19 -> 0.166925 | O19: =E19-$I19 -> -3901.0081 | P19: =F19-$I19 -> -27446.088
A20: =ROW()-11 -> 9 | B20: =EST!B141 -> 09-00-00 Finishes | D20: =EST!F165 -> 2798966 | E20: =EST!H165 -> 2733592.8 | F20: =EST!J165 -> 2733592.8 | I20: 2792966.3 | N20: =D20-$I20 -> 5999.7276 | O20: =E20-$I20 -> -59373.495 | P20: =F20-$I20 -> -59373.495
A21: =ROW()-11 -> 10 | B21: =EST!B167 -> 10-00-00 Specialties | D21: =EST!F173 -> 159011.93 | E21: =EST!H173 -> 154928.73 | F21: =EST!J173 -> 154928.73 | I21: 158947.35 | N21: =D21-$I21 -> 64.58 | O21: =E21-$I21 -> -4018.62 | P21: =F21-$I21 -> -4018.62
A22: =ROW()-11 -> 11 | B22: =EST!B175 -> 11-00-00 Equipments | D22: =EST!F179 -> 129602.2 | E22: =EST!H179 -> 126274.2 | F22: =EST!J179 -> 126274.2 | I22: 129537.5 | N22: =D22-$I22 -> 64.7 | O22: =E22-$I22 -> -3263.3 | P22: =F22-$I22 -> -3263.3
A23: =ROW()-11 -> 12 | B23: =EST!B181 -> 12-00-00 Furnishings | D23: =EST!F185 -> 176956.85 | E23: =EST!H185 -> 172412.85 | F23: =EST!J185 -> 172412.85 | I23: 176970.8 | N23: =D23-$I23 -> -13.95 | O23: =E23-$I23 -> -4557.95 | P23: =F23-$I23 -> -4557.95
A24: =ROW()-11 -> 13 | B24: =EST!B187 -> 13-00-00 Special Construction | D24: =EST!F190 -> 0 | E24: =EST!H190 -> 0 | F24: =EST!J190 -> 0 | I24: 0 | N24: =D24-$I24 -> 0 | O24: =E24-$I24 -> 0 | P24: =F24-$I24 -> 0
A25: =ROW()-11 -> 14 | B25: =EST!B192 -> 14-00-00 Elevators | D25: =EST!F196 -> 607136.46 | E25: =EST!H196 -> 591546.06 | F25: =EST!J196 -> 591546.06 | I25: 607375 | N25: =D25-$I25 -> -238.54 | O25: =E25-$I25 -> -15828.94 | P25: =F25-$I25 -> -15828.94
A26: =ROW()-11 -> 15 | B26: =EST!B198 -> 21-00-00 Fire Suppression | D26: =EST!F204 -> 509436.34 | E26: =EST!H204 -> 496354.74 | F26: =EST!J204 -> 496354.74 | I26: 509383.64 | N26: =D26-$I26 -> 52.69625 | O26: =E26-$I26 -> -13028.904 | P26: =F26-$I26 -> -13028.904
A27: =ROW()-11 -> 16 | B27: =EST!B206 -> 22-00-00 Plumbing | D27: =EST!F212 -> 854469.38 | E27: =EST!H212 -> 833298.18 | F27: =EST!J212 -> 833298.18 | I27: 824473.58 | N27: =D27-$I27 -> 29995.795 | O27: =E27-$I27 -> 8824.5951 | P27: =F27-$I27 -> 8824.5951
A28: =ROW()-11 -> 17 | B28: =EST!B214 -> 23-00-00 Heating, Ventilation, & Air Conditioning (HVAC) | D28: =EST!F259 -> 4796399.8 | E28: =EST!H259 -> 4812099.8 | F28: =EST!J259 -> 3858768 | I28: 5775993.2 | N28: =D28-$I28 -> -979593.44 | O28: =E28-$I28 -> -963893.44 | P28: =F28-$I28 -> -1917225.2
A29: =ROW()-11 -> 18 | B29: =EST!B261 -> 26-00-00 Electrical | D29: =EST!F445 -> 2539348.4 | E29: =EST!H445 -> 2476522.5 | F29: =EST!J445 -> 2447072.9 | I29: 2554638.5 | N29: =D29-$I29 -> -15290.059 | O29: =E29-$I29 -> -78115.965 | P29: =F29-$I29 -> -107565.53
A30: =ROW()-11 -> 19 | B30: =EST!B447 -> 27-00-00 Communications | D30: =EST!F453 -> 168981.33 | E30: =EST!H453 -> 164642.13 | F30: =EST!J453 -> 164642.13 | I30: 168903.84 | N30: =D30-$I30 -> 77.4891 | O30: =E30-$I30 -> -4261.7109 | P30: =F30-$I30 -> -4261.7109
A31: =ROW()-11 -> 20 | B31: =EST!B455 -> 28-00-00 Electronic Safety & Security | D31: =EST!F461 -> 433170.43 | E31: =EST!H461 -> 422047.23 | F31: =EST!J461 -> 422047.23 | I31: 433275.29 | N31: =D31-$I31 -> -104.85581 | O31: =E31-$I31 -> -11228.056 | P31: =F31-$I31 -> -11228.056
A32: =ROW()-11 -> 21 | B32: =EST!B464 -> 31-00-00 Earthwork | D32: =EST!F475 -> 0 | E32: =EST!H475 -> -49395.556 | F32: =EST!J475 -> -49395.556 | N32: =D32-$I32 -> 0 | O32: =E32-$I32 -> -49395.556 | P32: =F32-$I32 -> -49395.556
A33: =ROW()-11 -> 22 | B33: =EST!B477 -> 32-00-00 Exterior Improvements | D33: =EST!F480 -> 0 | E33: =EST!H480 -> 0 | F33: =EST!J480 -> 0 | I33: 0 | N33: =D33-$I33 -> 0 | O33: =E33-$I33 -> 0 | P33: =F33-$I33 -> 0
A34: =ROW()-11 -> 23 | B34: =EST!B482 -> 33-00-00 Utilities | D34: =EST!F553 -> 1197001.7 | E34: =EST!H553 -> -338798.31 | F34: =EST!J553 -> -338798.31 | N34: =D34-$I34 -> 1197001.7 | O34: =E34-$I34 -> -338798.31 | P34: =F34-$I34 -> -338798.31
A35: =ROW()-11 -> 24 | D35: - | E35: - | F35: - | I35: -
A36: =ROW()-11 -> 25 | B36: Subtotal 1 | D36: =SUM(D10:D35) -> 28594818 | E36: =SUM(E10:E35) -> 26347019 | F36: =SUM(F10:F35) -> 25205527 | I36: 28305371 | K36: =SUM(F13:F34) -> 22914116 | N36: =D36-$I36 -> 289446.61 | O36: =E36-$I36 -> -1958352.2 | P36: =F36-$I36 -> -3099844.1
A37: =ROW()-11 -> 26 | B37: General Contractor's Office Overhead & Profit | C37: =BOE!F45 -> 0.08 | D37: =D36*$C$37 -> 2287585.4 | E37: =E36*$C$37 -> 2107761.5 | F37: =F36*$C$37 -> 2016442.2 | I37: 2264429.7
A38: =ROW()-11 -> 27 | D38: - | E38: - | F38: - | I38: -
A39: =ROW()-11 -> 28 | B39: Subtotal 2 | D39: =SUM(D36:D38) -> 30882403 | E39: =SUM(E36:E38) -> 28454781 | F39: =SUM(F36:F38) -> 27221969 | I39: 30569801
A40: =ROW()-11 -> 29 | B40: Design Contingency | C40: =BOE!F46 -> 0.1 | D40: =D39*$C$40 -> 3088240.3 | E40: =E39*$C$40 -> 2845478.1 | F40: =F39*$C$40 -> 2722196.9 | I40: 0
A41: =ROW()-11 -> 30 | D41: - | E41: - | F41: - | I41: -
A42: =ROW()-11 -> 31 | B42: Subtotal 3 | D42: =SUM(D39:D41) -> 33970644 | E42: =SUM(E39:E41) -> 31300259 | F42: =SUM(F39:F41) -> 29944166 | I42: 30569801
A43: =ROW()-11 -> 32 | B43: Escalation to (Midpoint of Construction) | C43: =BOE!F48 -> 0.084375 | D43: =D42*$C$43 -> 2866273.1 | E43: =E42*$C$43 -> 2640959.3 | F43: =F42*$C$43 -> 2526539 | I43: 2579327
A44: =ROW()-11 -> 33 | D44: - | E44: - | F44: - | I44: -
A45: =ROW()-11 -> 34 | B45: Total CONSTRUCTION Cost | D45: =SUM(D42:D44) -> 36836917 | E45: =SUM(E42:E44) -> 33941218 | F45: =SUM(F42:F44) -> 32470705 | I45: 33149128
A46: =ROW()-11 -> 35 | B46: Bid Contingency | C46: 0.05 | D46: =D45*$C$46 -> 1841845.8 | E46: =E45*$C$46 -> 1697060.9 | F46: =F45*$C$46 -> 1623535.3 | I46: 1657456.4 | L46: =1.1*1.08*1.1*1.05*1.084 -> 1.4873998
...

Sheet EST
B4: =TITLE!A14 -> COLLEGE OF TECHNOLOGY AT FARMINGDALE
B5: =TITLE!A18 -> Farmingdale, New York
B6: =TITLE!A21 -> Concept Estimate | J6: =TITLE!A24 -> 44263
B8: =TITLE!A17 -> NET ZERO CARBON STUDY | E8: 49847 | F8: SF | G8: =49847-1280 -> 48567 | H8: SF | I8: =49847-1280 -> 48567 | J8: SF
B10: Description | C10: Unit Price | D10: Unit | E10: Option-1 | G10: Option-2 | I10: Option-3 | J10: Amount
E11: Quantity | F11: Amount | G11: Quantity | H11: Amount | I11: Quantity | J11: Amount
A12: =ROW()-11 -> 1
A13: =ROW()-11 -> 2 | B13: 01-00-00 General Requirements
A14: =ROW()-11 -> 3
A15: =ROW()-11 -> 4 | B15: Site General Conditions - 10% | C15: 1 | D15: LS | E15: =SUM(F19:F555)/2*0.1 -> 2599528.9 | F15: =E15*$C15 -> 2599528.9 | G15: =SUM(H19:H555)/2*0.1 -> 2395183.6 | H15: =G15*$C15 -> 2395183.6 | I15: =SUM(J19:J555)/2*0.1 -> 2291411.6 | J15: =I15*$C15 -> 2291411.6
A16: =ROW()-11 -> 5 | F16: - | H16: - | J16: -
A17: =ROW()-11 -> 6 | B17: ="Subtotal " & B13 -> Subtotal 01-00-00 General Requirements | F17: =SUM(F13:F16) -> 2599528.9 | H17: =SUM(H13:H16) -> 2395183.6 | J17: =SUM(J13:J16) -> 2291411.6
A18: =ROW()-11 -> 7
A19: =ROW()-11 -> 8 | B19: 02-00-00 Existing Conditions
A20: =ROW()-11 -> 9
A21: =ROW()-11 -> 10 | F21: =E21*$C21 -> 0 | H21: =G21*$C21 -> 0 | J21: =I21*$C21 -> 0
A22: =ROW()-11 -> 11 | F22: - | H22: - | J22: -
A23: =ROW()-11 -> 12 | B23: ="Subtotal " & B19 -> Subtotal 02-00-00 Existing Conditions | F23: =SUM(F19:F22) -> 0 | H23: =SUM(H19:H22) -> 0 | J23: =SUM(J19:J22) -> 0
A24: =ROW()-11 -> 13
A25: =ROW()-11 -> 14 | B25: 03-00-00 Concrete
A26: =ROW()-11 -> 15 | B26: Concrete revisions based on reducing Basement area by 1,400 square feet at south and 460 square feet at north | L26: GM
A27: =ROW()-11 -> 16
A28: =ROW()-11 -> 17 | B28: DEDUCT
A29: =ROW()-11 -> 18 | B29: Concrete slab on grade at basement - 1,400 SF + 460 SF - Options 2 & 3 | C29: =11.7*1.075 -> 12.5775 | D29: SF | E29: 0 | F29: =E29*$C29 -> 0 | G29: =-(1400+460) -> -1860 | H29: =G29*$C29 -> -23394.15 | I29: =-(1400+460) -> -1860 | J29: =I29*$C29 -> -23394.15 | L29: GM
A30: =ROW()-11 -> 19
A31: =ROW()-11 -> 20 | B31: Concrete fill on deck at first floor - 820 SF (exclude areaway) + 460 SF - Options 2 & 3 | C31: =9.36*1.075 -> 10.062 | D31: SF | E31: 0 | F31: =E31*$C31 -> 0 | G31: =-(820+460) -> -1280 | H31: =G31*$C31 -> -12879.36 | I31: =-(820+460) -> -1280 | J31: =I31*$C31 -> -12879.36 | L31: GM
A32: =ROW()-11 -> 21
A33: =ROW()-11 -> 22 | B33: Concrete foundation walls / areaway walls at basement - Options 2 & 3 | C33: =1172*1.075 -> 1259.9 | D33: CY | E33: 0 | F33: =E33*$C33 -> 0 | G33: =(-236*16*1)/27+(174*16*1)/27 -> -36.740741 | H33: =G33*$C33 -> -46289.659 | I33: =(-236*16*1)/27+(174*16*1)/27 -> -36.740741 | J33: =I33*$C33 -> -46289.659 | L33: GM
A34: =ROW()-11 -> 23 | B34: Deduct - 236 LF x 16' high x 1' th / Add 174 LF x 16' high x 1' th
A35: =ROW()-11 -> 24
A36: =ROW()-11 -> 25 | B36: Concrete encasement of steel columns at basement reduced building perimeter walls - Options 2 & 3 | C36: =1290*1.075 -> 1386.75 | D36: CY | E36: 0 | F36: =E36*$C36 -> 0 | G36: -3 | H36: =G36*$C36 -> -4160.25 | I36: -3 | J36: =I36*$C36 -> -4160.25 | L36: GM
A37: =ROW()-11 -> 26 | B37: Deduct - 1' x 1' x 15' high x 5 each
A38: =ROW()-11 -> 27
A39: =ROW()-11 -> 28 | B39: Concrete perimeter wall footings at building and areaway walls at basement - Options 2 & 3 | C39: =936*1.075 -> 1006.2 | D39: CY | E39: 0 | F39: =E39*$C39 -> 0 | G39: =(-236*2.5*1)/27+(174*2.5*1)/27 -> -5.7407407 | H39: =G39*$C39 -> -5776.3333 | I39: =(-236*2.5*1)/27+(174*2.5*1)/27 -> -5.7407407 | J39: =I39*$C39 -> -5776.3333 | L39: GM
A40: =ROW()-11 -> 29 | B40: Deduct - 236 LF x 2.5' x 1' / Add 174 LF x 2.5' x 1'
A41: =ROW()-11 -> 30
A42: =ROW()-11 -> 31 | B42: ADD
A43: =ROW()-11 -> 32
A44: =ROW()-11 -> 33 | B44: Add back concrete slab on grade at first floor- 1,400 SF + 460 SF (Note : 820 SF of this will be in site at deleted areaway) - Options 2 & 3 | C44: =11.7*1.075 -> 12.5775 | D44: SF | E44: 0 | F44: =E44*$C44 -> 0 | G44: =(1400+460) -> 1860 | H44: =G44*$C44 -> 23394.15 | I44: =(1400+460) -> 1860 | J44: =I44*$C44 -> 23394.15 | L44: GM
A45: =ROW()-11 -> 34
...

Sheet SUM SITE
B4: =SUM!B4 -> COLLEGE OF TECHNOLOGY AT FARMINGDALE | F4: =TITLE!A24 -> 44263
B5: =SUM!B5 -> NET ZERO CARBON STUDY
B6: =SUM!B6 -> Concept Estimate
A8: SUMMARY OF TRADES-SITE
B10: Description | D10: Material | E10: Labor | F10: ='EST SITE'!I10 -> Total
A12: =ROW()-11 -> 1 | B12: ='EST SITE'!B13 -> 01-00-00 General Requirements | D12: ='EST SITE'!F17 -> 303540.95 | E12: ='EST SITE'!H17 -> 404744.19 | F12: ='EST SITE'!J17 -> 708285.14
A13: =ROW()-11 -> 2 | B13: ='EST SITE'!B19 -> 02-00-01 Site Clearing | D13: ='EST SITE'!F53 -> 181844.51 | E13: ='EST SITE'!H53 -> 487937.68 | F13: ='EST SITE'!J53 -> 669782.19 | M13: =F13/$C$38 -> 3.0211876
A14: =ROW()-11 -> 3 | B14: ='EST SITE'!B55 -> 02-00-02 Earthwork | D14: ='EST SITE'!F79 -> 210524.56 | E14: ='EST SITE'!H79 -> 790635.84 | F14: ='EST SITE'!J79 -> 1001160.4 | M14: =F14/$C$38 -> 4.5159359
A15: =ROW()-11 -> 4 | B15: ='EST SITE'!B81 -> 02-00-03 Pavements | D15: ='EST SITE'!F115 -> 931689.3 | E15: ='EST SITE'!H115 -> 770566.21 | F15: ='EST SITE'!J115 -> 1702255.5 | M15: =F15/$C$38 -> 7.6783667
A16: =ROW()-11 -> 5 | B16: ='EST SITE'!B117 -> 02-00-04 Site Features | D16: ='EST SITE'!F178 -> 400253.26 | E16: ='EST SITE'!H178 -> 588787.04 | F16: ='EST SITE'!J178 -> 989040.3 | M16: =F16/$C$38 -> 4.4612657
A17: =ROW()-11 -> 6 | B17: ='EST SITE'!B180 -> 02-00-05 Concrete Walks | D17: ='EST SITE'!F183 -> 0 | E17: ='EST SITE'!H183 -> 0 | F17: ='EST SITE'!J183 -> 0 | M17: =F17/$C$38 -> 0
A18: =ROW()-11 -> 7 | B18: ='EST SITE'!B185 -> 02-00-06 Utilities-Plumbing | D18: ='EST SITE'!F264 -> 642827.73 | E18: ='EST SITE'!H264 -> 595424.71 | F18: ='EST SITE'!J264 -> 1238252.4 | M18: =F18/$C$38 -> 5.5853873
A19: =ROW()-11 -> 8 | B19: ='EST SITE'!B266 -> 02-00-07 Utilities- Heating/Cooling | D19: ='EST SITE'!F269 -> 0 | E19: ='EST SITE'!H269 -> 0 | F19: ='EST SITE'!J269 -> 0 | M19: =F19/$C$38 -> 0
A20: =ROW()-11 -> 9 | B20: ='EST SITE'!B271 -> 02-00-08 Utilities- Electrical | D20: ='EST SITE'!F375 -> 519224.44 | E20: ='EST SITE'!H375 -> 537019.31 | F20: ='EST SITE'!J375 -> 1056243.7 | M20: =F20/$C$38 -> 4.7644004
A21: =ROW()-11 -> 10 | B21: ='EST SITE'!B377 -> 02-00-09 Planting | D21: ='EST SITE'!F416 -> 128081.24 | E21: ='EST SITE'!H416 -> 193213.38 | F21: ='EST SITE'!J416 -> 321294.62 | M21: =F21/$C$38 -> 1.4492642
A22: =ROW()-11 -> 11 | B22: ='EST SITE'!B418 -> 02-00-10 Abatement | D22: ='EST SITE'!F422 -> 20964.435 | E22: ='EST SITE'!H422 -> 83857.74 | F22: ='EST SITE'!J422 -> 104822.17 | M22: =F22/$C$38 -> 0.47282156
A23: =ROW()-11 -> 12 | D23: - | E23: - | F23: -
A24: =ROW()-11 -> 13 | B24: Subtotal 1 | D24: =SUM(D10:D23) -> 3338950.4 | E24: =SUM(E10:E23) -> 4452186.1 | F24: =SUM(F10:F23) -> 7791136.5 | K24: =SUM(F13:F22) -> 7082851.4
A25: =ROW()-11 -> 14 | B25: General Contractor's Office Overhead & Profit | C25: =[1]BOE!F76 -> 0.08 | D25: =D24*$C$25 -> 267116.03 | E25: =E24*$C$25 -> 356174.89 | F25: =F24*$C$25 -> 623290.92
A26: =ROW()-11 -> 15 | D26: - | E26: - | F26: -
A27: =ROW()-11 -> 16 | B27: Subtotal 2 | D27: =SUM(D24:D26) -> 3606066.4 | E27: =SUM(E24:E26) -> 4808361 | F27: =SUM(F24:F26) -> 8414427.4
A28: =ROW()-11 -> 17 | B28: Design Contingency | C28: =[1]BOE!F77 -> 0 | D28: =D27*$C$28 -> 0 | E28: =E27*$C$28 -> 0 | F28: =F27*$C$28 -> 0
A29: =ROW()-11 -> 18 | D29: - | E29: - | F29: -
A30: =ROW()-11 -> 19 | B30: Subtotal 3 | D30: =SUM(D27:D29) -> 3606066.4 | E30: =SUM(E27:E29) -> 4808361 | F30: =SUM(F27:F29) -> 8414427.4
A31: =ROW()-11 -> 20 | B31: Escalation to (Midpoint of Construction) | C31: =[1]BOE!F79 -> 0.084375 | D31: =D30*$C$31 -> 304261.86 | E31: =E30*$C$31 -> 405705.46 | F31: =F30*$C$31 -> 709967.32
A32: =ROW()-11 -> 21 | D32: - | E32: - | F32: -
A33: =ROW()-11 -> 22 | B33: Total CONSTRUCTION Cost | D33: =SUM(D30:D32) -> 3910328.3 | E33: =SUM(E30:E32) -> 5214066.5 | F33: =SUM(F30:F32) -> 9124394.8
A34: =ROW()-11 -> 23 | B34: Bid Contingency | C34: 0.05 | D34: =D33*$C$34 -> 195516.41 | E34: =E33*$C$34 -> 260703.32 | F34: =F33*$C$34 -> 456219.74 | L34: =1.1*1.08*1.1*1.05 -> 1.37214
A35: =ROW()-11 -> 24 | D35: - | E35: - | F35: -
A36: =ROW()-11 -> 25 | B36: Total CONSTRUCTION Cost w/Bid Contingency | D36: =SUM(D33:D35) -> 4105844.7 | E36: =SUM(E33:E35) -> 5474769.8 | F36: =SUM(F33:F35) -> 9580614.5 | J36: =F36/F24 -> 1.2296813 | K36: =F36/K24*0.1 -> 0.13526494
B38: Total Gross Area in SF | C38: 221695
B39: Construction Cost per GSF | D39: =D33/$C$38 -> 17.638324 | E39: =E33/$C$38 -> 23.519098 | F39: =F33/$C$38 -> 41.157422
B40: Cost per GSF w/Bid Contingency | D40: =D36/$C$38 -> 18.52024 | E40: =E36/$C$38 -> 24.695053 | F40: =F36/$C$38 -> 43.215294

Sheet EST SITE
B4: =EST!B4 -> COLLEGE OF TECHNOLOGY AT FARMINGDALE
B5: =EST!B5 -> Farmingdale, New York
B6: =EST!B6 -> Concept Estimate | J6: =TITLE!A24 -> 44263 | M6: =3.75*2 -> 7.5
B8: =EST!B8 -> NET ZERO CARBON STUDY | M8: 1.075 | N8: 1.075
M9: PREVIOUS ESTIMATE
B10: Description | C10: Quantity | D10: Unit | E10: Material | G10: Labor | I10: Total | J10: Amount | M10: Material | N10: Labor
E11: Unit | F11: Amount | G11: Unit | H11: Amount | I11: Unit | J11: Amount | M11: Unit | N11: Unit
A12: =ROW()-11 -> 1
A13: =ROW()-11 -> 2 | B13: 01-00-00 General Requirements
A14: =ROW()-11 -> 3
A15: =ROW()-11 -> 4 | B15: Site General Conditions - 10% | C15: 1 | D15: LS | E15: =SUM(F19:F424)/2*0.1 -> 303540.95 | F15: =E15*$C15 -> 303540.95 | G15: =SUM(H19:H424)/2*0.1 -> 404744.19 | H15: =G15*$C15 -> 404744.19 | I15: =E15+G15 -> 708285.14 | J15: =I15*$C15 -> 708285.14
A16: =ROW()-11 -> 5 | F16: - | H16: - | J16: -
A17: =ROW()-11 -> 6 | B17: ="Subtotal " & B13 -> Subtotal 01-00-00 General Requirements | F17: =SUM(F13:F16) -> 303540.95 | H17: =SUM(H13:H16) -> 404744.19 | J17: =SUM(J13:J16) -> 708285.14
A18: =ROW()-11 -> 7
A19: =ROW()-11 -> 8 | B19: 02-00-01 Site Clearing
A20: =ROW()-11 -> 9
A21: =ROW()-11 -> 10 | B21: Construct and maintain 8' high construction fence and wind screen - 3,130 LF | C21: 25040 | D21: SF | E21: =M21*$M$8 -> 5.9125 | F21: =C21*E21 -> 148049 | G21: =N21*$N$8 -> 10.2125 | H21: =C21*G21 -> 255721 | I21: =E21+G21 -> 16.125 | J21: =I21*C21 -> 403770 | M21: 5.5 | N21: 9.5
A22: =ROW()-11 -> 11 | F22: =C22*E22 -> 0 | H22: =C22*G22 -> 0
A23: =ROW()-11 -> 12 | B23: Clear and grub site as required - original | C23: 59736 | D23: SF | E23: =M23*$M$8 -> 0.086 | F23: =C23*E23 -> 5137.296 | G23: =N23*$N$8 -> 0.129 | H23: =C23*G23 -> 7705.944 | I23: =E23+G23 -> 0.215 | J23: =I23*C23 -> 12843.24 | M23: 0.08 | N23: 0.12
A24: =ROW()-11 -> 13 | B24: Fine grading: | F24: =C24*E24 -> 0 | H24: =C24*G24 -> 0
A25: =ROW()-11 -> 14 | B25: Fine grading to achieve subgrade levels of pavements across site | C25: 59736 | D25: SF | E25: =M25*$M$8 -> 0.1075 | F25: =C25*E25 -> 6421.62 | G25: =N25*$N$8 -> 0.16125 | H25: =C25*G25 -> 9632.43 | I25: =E25+G25 -> 0.26875 | J25: =I25*C25 -> 16054.05 | M25: 0.1 | N25: 0.15
A26: =ROW()-11 -> 15 | F26: =C26*E26 -> 0 | H26: =C26*G26 -> 0
A27: =ROW()-11 -> 16 | B27: Soft landscaping: | F27: =C27*E27 -> 0 | H27: =C27*G27 -> 0
A28: =ROW()-11 -> 17 | B28: Protect trees | C28: 10 | D28: EA | E28: =M28*$M$8 -> 134.375 | F28: =C28*E28 -> 1343.75 | G28: =N28*$N$8 -> 403.125 | H28: =C28*G28 -> 4031.25 | I28: =E28+G28 -> 537.5 | J28: =I28*C28 -> 5375 | M28: 125 | N28: 375
A29: =ROW()-11 -> 18 | B29: Remove trees - 0" - 8" | C29: 5 | D29: EA | F29: =C29*E29 -> 0 | G29: =N29*$N$8 -> 553.625 | H29: =C29*G29 -> 2768.125 | I29: =E29+G29 -> 553.625 | J29: =I29*C29 -> 2768.125 | M29: 0 | N29: 515
A30: =ROW()-11 -> 19 | B30: Remove trees - 8"-35" | C30: 15 | D30: EA | F30: =C30*E30 -> 0 | G30: =N30*$N$8 -> 806.25 | H30: =C30*G30 -> 12093.75 | I30: =E30+G30 -> 806.25 | J30: =I30*C30 -> 12093.75 | M30: 0 | N30: 750
A31: =ROW()-11 -> 20 | B31: Remove trees >35" | C31: 2 | D31: EA | F31: =C31*E31 -> 0 | G31: =N31*$N$8 -> 1612.5 | H31: =C31*G31 -> 3225 | I31: =E31+G31 -> 1612.5 | J31: =I31*C31 -> 3225 | M31: 0 | N31: 1500
A32: =ROW()-11 -> 21 | B32: Remove trees - sizing not specified | C32: 5 | D32: EA | F32: =C32*E32 -> 0 | G32: =N32*$N$8 -> 1612.5 | H32: =C32*G32 -> 8062.5 | I32: =E32+G32 -> 1612.5 | J32: =I32*C32 -> 8062.5 | M32: 0 | N32: 1500
A33: =ROW()-11 -> 22 | F33: =C33*E33 -> 0 | H33: =C33*G33 -> 0
A34: =ROW()-11 -> 23 | B34: Hard landscaping: | F34: =C34*E34 -> 0 | H34: =C34*G34 -> 0
A35: =ROW()-11 -> 24 | B35: Remove existing bench | C35: 10 | D35: LF | F35: =C35*E35 -> 0 | G35: =N35*$N$8 -> 215 | H35: =C35*G35 -> 2150 | I35: =E35+G35 -> 215 | J35: =I35*C35 -> 2150 | M35: 0 | N35: 200
A36: =ROW()-11 -> 25 | B36: Remove existing curb | C36: 195 | D36: LF | F36: =C36*E36 -> 0 | G36: =N36*$N$8 -> 16.125 | H36: =C36*G36 -> 3144.375 | I36: =E36+G36 -> 16.125 | J36: =I36*C36 -> 3144.375 | M36: 0 | N36: 15
A37: =ROW()-11 -> 26 | B37: Remove existing retaining wall | C37: 139 | D37: LF | F37: =C37*E37 -> 0 | G37: =N37*$N$8 -> 107.5 | H37: =C37*G37 -> 14942.5 | I37: =E37+G37 -> 107.5 | J37: =I37*C37 -> 14942.5 | M37: 0 | N37: 100
A38: =ROW()-11 -> 27 | B38: Remove pavement | C38: 2451 | D38: SF | F38: =C38*E38 -> 0 | G38: =N38*$N$8 -> 2.6875 | H38: =C38*G38 -> 6587.0625 | I38: =E38+G38 -> 2.6875 | J38: =I38*C38 -> 6587.0625 | M38: 0 | N38: 2.5
A39: =ROW()-11 -> 28 | B39: Remove sign | C39: 3 | D39: EA | F39: =C39*E39 -> 0 | G39: =N39*$N$8 -> 107.5 | H39: =C39*G39 -> 322.5 | I39: =E39+G39 -> 107.5 | J39: =I39*C39 -> 322.5 | M39: 0 | N39: 100
A40: =ROW()-11 -> 29 | B40: Sawcut Pavement | C40: 554 | D40: LF | F40: =C40*E40 -> 0 | G40: =N40*$N$8 -> 10.75 | H40: =C40*G40 -> 5955.5 | I40: =E40+G40 -> 10.75 | J40: =I40*C40 -> 5955.5 | M40: 0 | N40: 10
A41: =ROW()-11 -> 30 | F41: =C41*E41 -> 0 | H41: =C41*G41 -> 0
A42: =ROW()-11 -> 31 | B42: Works within C-101 paths (Grey) area: | F42: =C42*E42 -> 0 | H42: =C42*G42 -> 0
A43: =ROW()-11 -> 32 | B43: Remove concrete pavement, curb & bitumen | C43: 24985 | D43: SF | F43: =C43*E43 -> 0 | G43: =N43*$N$8 -> 2.6875 | H43: =C43*G43 -> 67147.188 | I43: =E43+G43 -> 2.6875 | J43: =I43*C43 -> 67147.188 | M43: 0 | N43: 2.5
A44: =ROW()-11 -> 33 | B44: Extra-over removal of concrete pavement for removal of existing curb | C44: 310 | D44: LF | F44: =C44*E44 -> 0 | G44: =N44*$N$8 -> 16.125 | H44: =C44*G44 -> 4998.75 | I44: =E44+G44 -> 16.125 | J44: =I44*C44 -> 4998.75 | M44: 0 | N44: 15
...

Sheet ECM-SUM
B4: COLLEGE OF TECHNOLOGY AT FARMINGDALE | G4: =TITLE!A24 -> 44263
B5: NET ZERO CARBON STUDY | H5: =TITLE!A24 -> 44263
B8: Energy Conservation Measures (ECM}
B10: ID | C10: Name | D10: Description | E10: Performance | G10: Additional notes | H10: Total Amount
E11: Code Requirement / Baseline | F11: Proposed
B12: Envelope
B13: E1 | C13: High performance triple-glazing windows | D13: High performance triple glazed windows filled with argon. | E13: U-0.38 SHGC-0.36 VT-0.40 | F13: System: U-0.31; SHGC-0.24; VT-0.50 Center-of-glass : U-0.27;SHGC-0.27; VT-0.58 | G13: Triple glazing, e=0.05 on surface 2 and 4, LE LE CLR. Insulated vinyl frame, 1/ 2" air, 1/4" glass Manufacturers: Viracon, Interpane | H13: ='ECM-EST'!F28 -> 336271.34
B14: E2 | C14: Electrochromic glazing | D14: Replace existing windows with electrochromic glazing to optimize solar gain and lighting levels. | E14: U-0.38 SHGC-0.36 VT-0.40 | F14: U-0.28 SHGC-0.09-0.41 VT-0.01-0.60 | G14: SageGlass: 4mm clear w/SR2.0,0.89mm SentryGlas, 2.2mm SageGlass, 12mm air space w/90% Argon fill, 6mm clear Other manufacturers: View Glass, Halio by Kenestral | H14: ='ECM-EST'!F41 -> 506378.58
B15: E3 | C15: Roof lnsulation (Passive House level) | D15: Replace existing roof with R-60 continuous insulation to achieve Passive House certified values. | E15: U-0.032 R-30ci | F15: R-60c.i. | H15: ='ECM-EST'!F54 -> 206022.64
B16: E4 | C16: Wall insulation | D16: Increase wall insulation to R-30 to achieve Passive House certified level wall construction. | E16: U-0.064 R-13+R-7.5ci | F16: R-30c.i. | H16: ='ECM-EST'!F66 -> 315529.55
B17: E5 | C17: Below-grade wall insulation | D17: Increase below-grade wall insulation to R-15c.i. | E17: C-0.119 R-7.5ci | F17: R-15c.i. | H17: ='ECM-EST'!F80 -> 342350.02
B18: E6 | C18: Reduced infiltration | D18: Provide air-vapor barrier to achieve infiltration rates at Passive House (PHIUS+ 2015) levels | E18: 0.40 cfm /sf_f@ 0.3 in (75 Pa) | F18: 0.05 cfm/sf_f@ 50 Pa | H18: ='ECM-EST'!F89 -> 63253.162
B19: E7 | C19: Internal shading | E19: NR | F19: Add internal shading and control to reduce solar heat gain | G19: Black-out shades to provide reduced net amount of solar gain into the space | H19: ='ECM-EST'!F98 -> 45211.003
B20: Lighting
B21: L1a | C21: Upgrade interior lighting to be 20-30% better than baseline (With DALI) | D21: Optimize interior lighting layout to achieve 20-30% better than 100% CD baseline | E21: Total lighting load (inclusive of code exemptions/allowances) | F21: 20-30% improvement from total lighting load (inclusive of code exemptions/ allowances) | G21: To meet goal, the following will be required to ensure both energy efficient and visually viable results: -Downward revision of Classroom/Meeting Rm./Training Rm. avg. maintained lighting criteria from 40fc to 30-35fc. - Utilization of higher reflectance (+83%) lay in ceiling tile modules (Armstrong Calla, Ultima, Lyra, Optima) - Changing furniture/table top specifications in offices and classrooms to employ lighter value /higher reflectance materials (i.e. white or very light colors) - Re-specificationof most currently specified LED products to reflect higher efficacies - Re-specification of the currently designed 0-lOV lighting control system to reflect the use of the DALI (Digital Addressable Lighting Interface) based or comparable control system to allow for a Lumen Maintenance control protocol to be introduced - Con figuration of local controls in Offices and Classrooms to prevent activation of artificial lighting systems when average daylight levels in these rooms are above an average of 40fc | H21: ='ECM-EST'!F170 -> 262472.55
B22: L1b | C22: Upgrade interior lighting to be 20-30% better than baseline (With Out DALI) | D22: Optimize interior lighting layout to achieve 20-30% better than 100% CD baseline | E22: Total lighting load (inclusive of code exemptions/allowances) | F22: 20-30% improvement from total lighting load (inclusive of code exemptions/ allowances) | G22: To meet goal, the following will be required to ensure both energy efficient and visually viable results: -Downward revision of Classroom/Meeting Rm./Training Rm. avg. maintained lighting criteria from 40fc to 30-35fc. - Utilization of higher reflectance (+83%) lay in ceiling tile modules (Armstrong Calla, Ultima, Lyra, Optima) - Changing furniture/table top specifications in offices and classrooms to employ lighter value /higher reflectance materials (i.e. white or very light colors) - Re-specificationof most currently specified LED products to reflect higher efficacies - Re-specification of the currently designed 0-lOV lighting control system to reflect the use of the DALI (Digital Addressable Lighting Interface) based or comparable control system to allow for a Lumen Maintenance control protocol to be introduced - Con figuration of local controls in Offices and Classrooms to prevent activation of artificial lighting systems when average daylight levels in these rooms are above an average of 40fc | H22: ='ECM-EST'!F243 -> 14790.96
B23: L2 | C23: Upgrade exterior lighting to be 20-30% better than baseline | D23: Optimize exterior lighting layout to achieve 20-30% better than 100% CD baseline | E23: Total lighting load (inclusive of code exemptions/allowances) | F23: 20-30% improvement from total lighting load (inclusive of code exemptions/ allowances) | H23: Excluded
B24: Plug Loads
B25: P2 | C25: Plug Load Control | D25: Add controllable outlets to manage plug loads to comply with ASHRAE 90.1- 2016 requirements. | E25: NR | F25: 50% of 125 V receptacles in applicable spaces to be off20 mins after occupants leave space | H25: ='ECM-EST'!F281 -> 158838.37
B26: P3 | C26: Load reduction | D26: Reduce effective space load by 20%,e.g. by limiting the amount of time that equipment not in use is on | E26: NR | F26: 20% Equipment Power Density reduction, or equivalent reduction in the amount of time plug loads are on | H26: By Owner
B27: Data Center
B28: D1 | C28: Reduce Data Center by 15% | D28: Reduce Data Center energy usage by 15% through strategies involving consolidating IT system redundancies, upgrading Energy Star certified servers, and migrating to a cloud service. | E28: NR | F28: Reduced datacenter load by 15% | G28: Need feedback from IT consultant / ownership: what level of reduction is feasible (if any)? | H28: By Owner
B29: HVAC
B30: H1 | C30: Centralized GS HVAC | D30: Centralized GSHP (HR chiller) + central AHU, VAV w/reheat (hydro) | E30: Minimum efficiency requirements for HYAC | F30: Provide HYAC with performance that is at least 10% better than code | H30: Reflected as Concept Estimate
B31: H2 | C31: Centralized AS HVAC | D31: Centralized ASHP (air-cooled HR chiller) + central AHU, VAV w/ reheat (hydro) | E31: Minimum efficiency requirements for HYAC | F31: Provide HVAC with performance that is at least 10% better than code | H31: Reflected as Concept Estimate
B32: H3 | C32: Distributed HP HVAC | D32: Air-cooled chiller and electric boiler serving a condenser water loop. Condenser loop serves distributed heat pumps conditioning spaces+ DOAS | E32: Minimum efficiency requirements for HYAC | F32: Provide HVAC with performance that is at least 10% better than code | H32: Reflected as Concept Estimate
B33: Controls
B34: C1 | C34: Demand Control Ventilation | D34: Add demand control ventilation to reduce heating and cooling loads . | E34: Where required by code | F34: Applicable to all spaces | H34: ='ECM-EST'!F290 -> 166886.25
B35: C2 | C35: Relax setpoints | D35: Relax setpoints in transient spaces (corridors) from heating and cooling setpoints of 72F and 75F to 68F and 80F. | F35: Relax setpoints | H35: By Operation
B36: Water
B37: W1 | C37: Low Flow Faucets & Fixtures | D37: Upgrade to low flow faucets and fixtures to conserve water and reduce DHW loads. | F37: Kitchen faucet: 1.5 gpm Restroom faucet 0.35 gpm Shower: 1.5 gpm | H37: ='ECM-EST'!F299 -> 13014.748

Sheet ECM-SUM (2)
B4: =TITLE!A14 -> COLLEGE OF TECHNOLOGY AT FARMINGDALE | F4: =TITLE!A24 -> 44263
B5: =TITLE!A17 -> NET ZERO CARBON STUDY
B6: =TITLE!A21 -> Concept Estimate
A7: State University Construction Fund Construct School of Applied Social Sciences State University College of Technology at Farmingdale
A8: Energy Conservation Measures (ECM}
A9: ID | B9: Name | C9: Description | D9: Performance | F9: Additional notes | G9: Total Amount
D10: Code Requirement / Baseline | E10: Proposed
A11: Envelope
A12: El- | B12: High performance triple-glazing windows | C12: High performance triple glazed windows filled with argon. | D12: U-0.38 SHGC-0.36 VT-0.40 | E12: System: U-0.31; SHGC-0.24; VT-0.50 Center-of-glass : U-0.27;SHGC-0.27; VT-0.58 | F12: Triple glazing, e=0.05 on surface 2 and 4, LE LE CLR. Insulated vinyl frame, 1/ 2" air, 1/4" glass Manufacturers: Viracon, Interpane | G12: ='ECM-EST'!F28 -> 336271.34
A13: E2- | B13: Electrochromic glazing | C13: Replace existing windows with electrochromic glazing to optimize solar gain and lighting levels. | D13: U-0.38 SHGC-0.36 VT-0.40 | E13: U-0.28 SHGC-0.09-0.41 VT-0.01-0.60 | F13: SageGlass: 4mm clear w/SR2.0,0.89mm SentryGlas, 2.2mm SageGlass, 12mm air space w/90% Argon fill, 6mm clear Other manufacturers: View Glass, Halio by Kenestral | G13: ='ECM-EST'!F41 -> 506378.58
A14: E3- | B14: Rooflnsulation (Passive House level) | C14: Replace existing roof with R-60 continuous insulation to achieve Passive House certified values. | D14: U-0.032 R-30ci | E14: R-60c.i. | G14: ='ECM-EST'!F54 -> 206022.64
A15: E4- | B15: Wall insulation | C15: Increase wall insulation to R-30 to achieve Passive House certified level wall construction. | D15: U-0.064 R-13+R-7.5ci | E15: R-30c.i. | G15: ='ECM-EST'!F66 -> 315529.55
A16: E5- | B16: Below-grade wall insulation | C16: Increase below-grade wall insulation to R-15c.i. | D16: C-0.119 R-7.5ci | E16: R-15c.i. | G16: ='ECM-EST'!F80 -> 342350.02
A17: E6- | B17: Reduced infiltration | C17: Provide air-vapor barrier to achieve infiltration rates at Passive House (PHIUS+ 2015) levels | D17: 0.40 cfm /sf_f@ 0.3 in (75 Pa) | E17: 0.05 cfm/sf_f@ 50 Pa | G17: ='ECM-EST'!F89 -> 63253.162
A18: E7- | B18: Internal shading | D18: NR | E18: Add internal shading and control to reduce solar heat gain | F18: Black-out shades to provide reduced net amount of solar gain into the space | G18: ='ECM-EST'!F98 -> 45211.003
A19: Lighting
A20: L1- | B20: Upgrade interior lighting to be 20-30% better than baseline | C20: Optimize interior lighting layout to achieve 20-30% better than 100% CD baseline | D20: Total lighting load (inclusive of code exemptions/allowances) | E20: 20-30% improvement from total lighting load (inclusive of code exemptions/ allowances) | F20: To meet goal, the following will be required to ensure both energy efficient and visually viable results: -Downward revision of Classroom/Meeting Rm./Training Rm. avg. maintained lighting criteria from 40fc to 30-35fc. - Utilization of higher reflectance (+83%) lay in ceiling tile modules (Armstrong Calla, Ultima, Lyra, Optima) - Changing furniture/table top specifications in offices and classrooms to employ lighter value /higher reflectance materials (i.e. white or very light colors) - Re-specificationof most currently specified LED products to reflect higher efficacies - Re-specification of the currently designed 0-lOV lighting control system to reflect the use of the DALI (Digital Addressable Lighting Interface) based or comparable control system to allow for a Lumen Maintenance control protocol to be introduced - Con figuration of local controls in Offices and Classrooms to prevent activation of artificial lighting systems when average daylight levels in these rooms are above an average of 40fc | G20: ='ECM-EST'!F170 -> 262472.55
A21: L2- | B21: Upgrade exterior lighting to be 20-30% better than baseline | C21: Optimize exterior lighting layout to achieve 20-30% better than 100% CD baseline | D21: Total lighting load (inclusive of code exemptions/allowances) | E21: 20-30% improvement from total lighting load (inclusive of code exemptions/ allowances) | G21: ='ECM-EST'!#REF! -> #REF!
A22: Plug Loads
A23: P2- | B23: Plug Load Control | C23: Add controllable outlets to manage plug loads to comply with ASHRAE 90.1- 2016 requirements. | D23: NR | E23: 50% of 125 V receptacles in applicable spaces to be off20 mins after occupants leave space | G23: ='ECM-EST'!F281 -> 158838.37
A24: P3- | B24: Load reduction | C24: Reduce effective space load by 20%,e.g. by limiting the amount of time that equipment not in use is on | D24: NR | E24: 20% Equipment Power Density reduction, or equivalent reduction in the amount of time plug loads are on | G24: ='ECM-EST'!#REF! -> #REF!
A25: Data Center
A26: 1- | B26: Reduce Data Center by 15% | C26: Reduce Data Center energy usage by 15% through strategies involving consolidating IT system redundancies, upgrading Energy Star certified servers, and migrating to a cloud service. | D26: NR | E26: Reduced datacenter load by 15% | F26: Need feedback from IT consultant / ownership: what level of reduction is feasible (if any)? | G26: ='ECM-EST'!#REF! -> #REF!
A27: HVAC
A28: Hl- | B28: Centralized GS HVAC | C28: Centralized GSHP (HR chiller) + central AHU, VAV w/reheat (hydro) | D28: Minimum efficiency requirements for HYAC | E28: Provide HYAC with performance that is at least 10% better than code | G28: ='ECM-EST'!#REF! -> #REF!
A29: H2- | B29: Centralized AS HVAC | C29: Centralized ASHP (air-cooled HR chiller) + central AHU, VAV w/ reheat (hydro) | D29: Minimum efficiency requirements for HYAC | E29: Provide HVAC with performance that is at least 10% better than code | G29: ='ECM-EST'!#REF! -> #REF!
A30: H3- | B30: Distributed HP HVAC | C30: Air-cooled chiller and electric boiler serving a condenser water loop. Condenser loop serves distributed heat pumps conditioning spaces+ DOAS | D30: Minimum efficiency requirements for HYAC | E30: Provide HVAC with performance that is at least 10% better than code | G30: ='ECM-EST'!#REF! -> #REF!
A31: Controls
A32: Cl- | B32: Demand Control Ventilation | C32: Add demand control ventilation to reduce heating and cooling loads . | D32: Where required by code | E32: Applicable to all spaces | G32: ='ECM-EST'!F290 -> 166886.25
A33: C2- | B33: Relax setpoints | C33: Relax setpoints in transient spaces (corridors) from heating and cooling setpoints of 72F and 75F to 68F and 80F. | E33: Relax setpoints | G33: ='ECM-EST'!#REF! -> #REF!
A34: Water
A35: Wl- | B35: Low Flow Faucets & Fixtures | C35: Upgrade to low flow faucets and fixtures to conserve water and reduce DHW loads. | E35: Kitchen faucet: 1.5 gpm Restroom faucet 0.35 gpm Shower: 1.5 gpm | G35: ='ECM-EST'!F299 -> 13014.748

Sheet ECM-EST
B4: =EST!B4 -> COLLEGE OF TECHNOLOGY AT FARMINGDALE
B5: =EST!B5 -> Farmingdale, New York
B8: Energy Conservation Methods (ECM) | F8: =TITLE!A24 -> 44263
B10: Description | C10: Qty | D10: Unit | E10: Unit Rate | F10: Amount
A12: =ROW()-11 -> 1
A13: =ROW()-11 -> 2 | B13: =_xlfn.CONCAT('ECM-SUM'!B13,'ECM-SUM'!C13) -> E1 High performance triple-glazing windows
A14: =ROW()-11 -> 3
A15: =ROW()-11 -> 4 | B15: ADD
A16: =ROW()-11 -> 5 | B16: High performance triple glazed windows w/ insulated vinyl frame, 1/2" air, 1/4" glass | C16: 2533 | D16: SF | E16: =100.92+20 -> 120.92 | F16: =C16*E16 -> 306290.36
A17: =ROW()-11 -> 6 | B17: High performance triple glazed windows w/ insulated vinyl frame, 1/2" air, 1/4" glass at curtain wall | C17: 1974 | D17: SF | E17: =184.09+20 -> 204.09 | F17: =C17*E17 -> 402873.66
A18: =ROW()-11 -> 7 | B18: High performance triple glazed windows w/ insulated vinyl frame, 1/2" air, 1/4" glass at Storefront | C18: 6260 | D18: SF | E18: =106.21+20 -> 126.21 | F18: =C18*E18 -> 790074.6
A19: =ROW()-11 -> 8 | B19: Allow for 3/4" shear studs | C19: 2000 | D19: EA | E19: 5.37 | F19: =C19*E19 -> 10740
A20: =ROW()-11 -> 9 | B20: DEDUCT
A21: =ROW()-11 -> 10 | B21: Exterior Wall Type 1 - 3 1/4" Thermally broken aluminum framed fixed windows with 1" insulated glass including metal infill panels (at exterior masonry walls) Double glazed - See drawing A-210 | C21: -2533 | D21: SF | E21: 100.92 | F21: =C21*E21 -> -255630.36
A22: =ROW()-11 -> 11 | B22: Exterior full height Curtainwall - vision and spandrel panels - 1" insulated spandrel glazing / 2 1/2" galv metal stud / vapor barrier Double glazed- see sections 1, 7 & 8 on drawing A-215 | C22: -1974 | D22: SF | E22: =184.09 -> 184.09 | F22: =C22*E22 -> -363393.66
A23: =ROW()-11 -> 12 | B23: Exterior Type SF glass storefront system including all aluminum mullions at first to third floors - see sections SF-1 to SF- 64 on drawings A-211 to A-214 | C23: -6260 | D23: SF | E23: =106.21 -> 106.21 | F23: =C23*E23 -> -664874.6
A24: =ROW()-11 -> 13 | F24: -
A25: =ROW()-11 -> 14 | B25: Subtotal | F25: =SUM(F13:F24) -> 226080
A26: =ROW()-11 -> 15 | B26: Markup | C26: =SUM!$L$46-1 -> 0.48739976 | F26: =C26*F25 -> 110191.34
A27: =ROW()-11 -> 16 | F27: -
A28: =ROW()-11 -> 17 | B28: ="Total " & B13 -> Total E1 High performance triple-glazing windows | F28: =SUM(F25:F27) -> 336271.34
A29: =ROW()-11 -> 18
A30: =ROW()-11 -> 19 | B30: =_xlfn.CONCAT('ECM-SUM'!B14,'ECM-SUM'!C14) -> E2 Electrochromic glazing
A31: =ROW()-11 -> 20 | B31: ADD
A32: =ROW()-11 -> 21 | B32: Electrochromic glazing at exterior windows | C32: =2533 -> 2533 | D32: SF | E32: =100.92*0.35 -> 35.322 | F32: =C32*E32 -> 89470.626
A33: =ROW()-11 -> 22 | B33: Electrochromic glazing at curtainwall | C33: =(1974) -> 1974 | D33: SF | E33: =184.09*0.35 -> 64.4315 | F33: =C33*E33 -> 127187.78
A34: =ROW()-11 -> 23 | B34: Electrochromic glazing at Storefront | C34: 6260 | D34: SF | E34: =106.21*0.35 -> 37.1735 | F34: =C34*E34 -> 232706.11
A35: =ROW()-11 -> 24 | B35: DEDUCT
A36: =ROW()-11 -> 25 | B36: Motorized Shades at classrooms ( including power, control and wiring as required) | C36: -2533 | D36: SF | E36: 43 | F36: =C36*E36 -> -108919
A37: =ROW()-11 -> 26 | F37: -
A38: =ROW()-11 -> 27 | B38: Subtotal | F38: =SUM(F31:F37) -> 340445.52
A39: =ROW()-11 -> 28 | B39: Markup | C39: =SUM!$L$46-1 -> 0.48739976 | F39: =C39*F38 -> 165933.06
A40: =ROW()-11 -> 29 | F40: -
A41: =ROW()-11 -> 30 | B41: ="Total " & B30 -> Total E2 Electrochromic glazing | F41: =SUM(F38:F40) -> 506378.58
A42: =ROW()-11 -> 31
A43: =ROW()-11 -> 32 | B43: =_xlfn.CONCAT('ECM-SUM'!B15,'ECM-SUM'!C15) -> E3 Roof lnsulation (Passive House level)
A44: =ROW()-11 -> 33 | B44: ADD
A45: =ROW()-11 -> 34 | B45: Increase in reinforced concrete parapet wall 8" | C45: =655*0.67*0.67/27 -> 10.889981 | D45: CY | E45: 996.14 | F45: =C45*E45 -> 10847.946
A46: =ROW()-11 -> 35 | B46: Rigid insulation increase to R-60 | C46: 15958 | D46: SF | E46: 8 | F46: =C46*E46 -> 127664
A47: =ROW()-11 -> 36 | B47: Second floor roof area - 2,085 SF includes canopies
...
